<?xml version="1.0"?>
<!-- Base on http://tu-darmstadt-ros-pkg.googlecode.com/svn/trunk/hector_models/hector_sensors_description/urdf/hokuyo_utm30lx.urdf.xacro -->
<robot xmlns:sensor="http://playerstage.sourceforge.net/gazebo/xmlschema/#sensor"
xmlns:controller="http://playerstage.sourceforge.net/gazebo/xmlschema/#controller"
xmlns:interface="http://playerstage.sourceforge.net/gazebo/xmlschema/#interface"
xmlns:xacro="http://ros.org/wiki/xacro">  

	<xacro:include filename="$(find gki_cube_gripper_description)/urdf/common_properties.urdf.xacro" />

  <xacro:macro name="cube_gripper" params="name parent *origin">
    <joint name="${name}_joint" type="fixed">
      <insert_block name="origin" />
      <parent link="${parent}"/>
      <child link="${name}_link"/>
    </joint>

    <joint name="${name}_elbow_joint" type="revolute">
      <axis xyz="0 1 0"/>
      <limit effort="1000.0" lower="-1.6" upper="0" velocity="0.33"/>
      <origin xyz="0.03 0 0" rpy="0 0 0" />
      <parent link="${name}_link"/>
      <child link="${name}_arm_link"/>
    </joint>

    <joint name="${name}_right_finger_joint" type="revolute">
      <axis xyz="0 0 1"/>
      <limit effort="1000.0" lower="-1.0" upper="0" velocity="0.33"/>
      <origin xyz="0.175 -0.025 0" rpy="0 0 0" />
      <parent link="${name}_arm_link"/>
      <child link="${name}_right_finger_link"/>
    </joint>

    <joint name="${name}_left_finger_joint" type="revolute">
      <axis xyz="0 0 1"/>
      <limit effort="1000.0" lower="-1.0" upper="0" velocity="0.33"/>
      <origin xyz="0.175 0.025 0" rpy="${180*M_DEGREES} 0 0" />
      <parent link="${name}_arm_link"/>
      <child link="${name}_left_finger_link"/>
      <mimic joint="${name}_right_finger_joint" multiplier="1" />
    </joint>

    <link name="${name}_link">
      <inertial>
        <mass value="0.200" />
        <origin xyz="0 0 0" rpy="0 0 0" />
        <inertia ixx="2.632e-4" ixy="0" ixz="0" iyy="2.632e-4" iyz="0" izz="1.62e-4" />
      </inertial>
      <visual>
        <origin xyz="0 0 0" rpy="0 0 0" />
        <geometry>
          <mesh scale="0.001 0.001 0.001"  filename="package://gki_cube_gripper_description/meshes/cube_gripper_elbow.stl"/>
        </geometry>
        <xacro:insert_block name="material_dark_grey" />
      </visual>
      <collision>
        <origin xyz="0 0 -0.021" rpy="0 0 0" />
        <geometry>
          <box size="0.13 0.13 0.07" />
        </geometry>
      </collision>
    </link>

    <link name="${name}_arm_link">
      <inertial>
        <mass value="0.200" />
        <origin xyz="0 0 0" rpy="0 0 0" />
        <inertia ixx="2.632e-4" ixy="0" ixz="0" iyy="2.632e-4" iyz="0" izz="1.62e-4" />
      </inertial>
      <visual>
        <origin xyz="0 0 0" rpy="0 0 0" />
        <geometry>
          <!--
          <box size="0.13 0.13 0.07" />
          -->
          <mesh scale="0.001 0.001 0.001" filename="package://gki_cube_gripper_description/meshes/cube_gripper_arm.stl"/>
        </geometry>
        <xacro:insert_block name="material_dark_grey" />
      </visual>
      <collision>
        <origin xyz="0 0 -0.021" rpy="0 0 0" />
        <geometry>
          <box size="0.13 0.13 0.07" />
        </geometry>
      </collision>
    </link>

    <link name="${name}_right_finger_link">
      <inertial>
        <mass value="0.200" />
        <origin xyz="0 0 0" rpy="0 0 0" />
        <inertia ixx="2.632e-4" ixy="0" ixz="0" iyy="2.632e-4" iyz="0" izz="1.62e-4" />
      </inertial>
      <visual>
        <origin xyz="0 0 0" rpy="0 0 0" />
        <geometry>
          <!--
          <box size="0.13 0.13 0.07" />
          -->
          <mesh scale="0.001 0.001 0.001" filename="package://gki_cube_gripper_description/meshes/cube_gripper_finger.stl"/>
        </geometry>
        <xacro:insert_block name="material_dark_grey" />
      </visual>
      <collision>
        <origin xyz="0 0 -0.021" rpy="0 0 0" />
        <geometry>
          <box size="0.13 0.13 0.07" />
        </geometry>
      </collision>
    </link>

    <link name="${name}_left_finger_link">
      <inertial>
        <mass value="0.200" />
        <origin xyz="0 0 0" rpy="0 0 0" />
        <inertia ixx="2.632e-4" ixy="0" ixz="0" iyy="2.632e-4" iyz="0" izz="1.62e-4" />
      </inertial>
      <visual>
        <origin xyz="0 0 0" rpy="0 0 0" />
        <geometry>
          <!--
          <box size="0.13 0.13 0.07" />
          -->
          <mesh scale="0.001 0.001 0.001" filename="package://gki_cube_gripper_description/meshes/cube_gripper_finger.stl"/>
        </geometry>
        <xacro:insert_block name="material_dark_grey" />
      </visual>
      <collision>
        <origin xyz="0 0 -0.021" rpy="0 0 0" />
        <geometry>
          <box size="0.13 0.13 0.07" />
        </geometry>
      </collision>
    </link>

<!--
    <link name="${name}_right_elbow_link">
      <inertial>
        <mass value="0.200" />
        <origin xyz="0 0 0" rpy="0 0 0" />
        <inertia ixx="2.632e-4" ixy="0" ixz="0" iyy="2.632e-4" iyz="0" izz="1.62e-4" />
      </inertial>
      <visual>
        <origin xyz="0 0 0" rpy="0 0 0" />
        <geometry>
          <mesh filename="package://gki_cube_gripper_description/meshes/cube_gripper_elbow.stl"/>
        </geometry>
        <xacro:insert_block name="material_dark_grey" />
      </visual>
      <collision>
        <origin xyz="0 0 -0.021" rpy="0 0 0" />
        <geometry>
          <box size="0.13 0.13 0.07" />
        </geometry>
      </collision>
    </link>

    <link name="${name}_left_elbow_link">
      <inertial>
        <mass value="0.200" />
        <origin xyz="0 0 0" rpy="${180 * M_DEGREES} 0 0" />
        <inertia ixx="2.632e-4" ixy="0" ixz="0" iyy="2.632e-4" iyz="0" izz="1.62e-4" />
      </inertial>
      <visual>
        <origin xyz="0 0 0" rpy="0 0 0" />
        <geometry>
          <mesh filename="package://gki_cube_gripper_description/meshes/cube_gripper_elbow.stl"/>
        </geometry>
        <xacro:insert_block name="material_dark_grey" />
      </visual>
      <collision>
        <origin xyz="0 0 -0.021" rpy="0 0 0" />
        <geometry>
          <box size="0.13 0.13 0.07" />
        </geometry>
      </collision>
    </link>
-->
  </xacro:macro>
</robot>

